Workbook

Sheet 加工表
A1: Fun | B1: Index | C1: Algorithms
C2: SO | D2: TCM-SO | E2: BDS-SO | F2: EOBL-SO | G2: TB-SO | H2: TE-SO | I2: BE-SO | J2: TBESO
A3: F1 | B3: Mean | C3: =辅助表!C3 -> 2.3020981e+09 | D3: =辅助表!D3 -> 2.5983919e+10 | E3: =辅助表!E3 -> 35688240 | F3: =辅助表!F3 -> 4.9530994e+08 | G3: =辅助表!G3 -> 4.2767912e+08 | H3: =辅助表!H3 -> 4.8563039e+08 | I3: =辅助表!I3 -> 25992311 | J3: =辅助表!J3 -> 24394091
B4: Std | C4: =辅助表!C4 -> 1.02555e+09 | D4: =辅助表!D4 -> 6.7771665e+09 | E4: =辅助表!E4 -> 20432904 | F4: =辅助表!F4 -> 2.7875701e+08 | G4: =辅助表!G4 -> 2.0654322e+08 | H4: =辅助表!H4 -> 2.6011969e+08 | I4: =辅助表!I4 -> 14068292 | J4: =辅助表!J4 -> 14882927
B5: mean_Rank | C5: =RANK(C3,3:3,1) -> 7 | D5: =RANK(D3,3:3,1) -> 8 | E5: =RANK(E3,3:3,1) -> 3 | F5: =RANK(F3,3:3,1) -> 6 | G5: =RANK(G3,3:3,1) -> 4 | H5: =RANK(H3,3:3,1) -> 5 | I5: =RANK(I3,3:3,1) -> 2 | J5: =RANK(J3,3:3,1) -> 1
B6: std_rank | C6: =RANK(C4,4:4,1) -> 7 | D6: =RANK(D4,4:4,1) -> 8 | E6: =RANK(E4,4:4,1) -> 3 | F6: =RANK(F4,4:4,1) -> 6 | G6: =RANK(G4,4:4,1) -> 4 | H6: =RANK(H4,4:4,1) -> 5 | I6: =RANK(I4,4:4,1) -> 1 | J6: =RANK(J4,4:4,1) -> 2
B7: sum_rank | C7: =C5+C6 -> 14 | D7: =D5+D6 -> 16 | E7: =E5+E6 -> 6 | F7: =F5+F6 -> 12 | G7: =G5+G6 -> 8 | H7: =H5+H6 -> 10 | I7: =I5+I6 -> 3 | J7: =J5+J6 -> 3
B8: RANK | C8: =RANK(C7,7:7,1) -> 7 | D8: =RANK(D7,7:7,1) -> 8 | E8: =RANK(E7,7:7,1) -> 3 | F8: =RANK(F7,7:7,1) -> 6 | G8: =RANK(G7,7:7,1) -> 4 | H8: =RANK(H7,7:7,1) -> 5 | I8: =RANK(I7,7:7,1) -> 1 | J8: =RANK(J7,7:7,1) -> 1
B9: ‘-/=/+ | C9: =IF(C8>C8,"-",IF(C8=C8,"=","+")) -> = | D9: =IF(D8>C8,"-",IF(D8=C8,"=","+")) -> - | E9: =IF(E8>C8,"-",IF(E8=C8,"=","+")) -> + | F9: =IF(F8>C8,"-",IF(F8=C8,"=","+")) -> + | G9: =IF(G8>C8,"-",IF(G8=C8,"=","+")) -> + | H9: =IF(H8>C8,"-",IF(H8=C8,"=","+")) -> + | I9: =IF(I8>C8,"-",IF(I8=C8,"=","+")) -> + | J9: =IF(J8>C8,"-",IF(J8=C8,"=","+")) -> +
A10: F2 | B10: Mean | C10: =辅助表!C5 -> 1.1421454e+32 | D10: =辅助表!D5 -> 5.5838833e+37 | E10: =辅助表!E5 -> 3.6232161e+28 | F10: =辅助表!F5 -> 6.0032476e+31 | G10: =辅助表!G5 -> 7.7946279e+30 | H10: =辅助表!H5 -> 7.6083724e+32 | I10: =辅助表!I5 -> 6.8063257e+27 | J10: =辅助表!J5 -> 1.0184732e+27
B11: Std | C11: =辅助表!C6 -> 3.6284939e+32 | D11: =辅助表!D6 -> 2.4614382e+38 | E11: =辅助表!E6 -> 1.0309384e+29 | F11: =辅助表!F6 -> 2.3171128e+32 | G11: =辅助表!G6 -> 3.7168277e+31 | H11: =辅助表!H6 -> 4.157885e+33 | I11: =辅助表!I6 -> 3.2331306e+28 | J11: =辅助表!J6 -> 3.1997278e+27
B12: mean_Rank | C12: =RANK(C10,10:10,1) -> 6 | D12: =RANK(D10,10:10,1) -> 8 | E12: =RANK(E10,10:10,1) -> 3 | F12: =RANK(F10,10:10,1) -> 5 | G12: =RANK(G10,10:10,1) -> 4 | H12: =RANK(H10,10:10,1) -> 7 | I12: =RANK(I10,10:10,1) -> 2 | J12: =RANK(J10,10:10,1) -> 1
B13: std_rank | C13: =RANK(C11,11:11,1) -> 6 | D13: =RANK(D11,11:11,1) -> 8 | E13: =RANK(E11,11:11,1) -> 3 | F13: =RANK(F11,11:11,1) -> 5 | G13: =RANK(G11,11:11,1) -> 4 | H13: =RANK(H11,11:11,1) -> 7 | I13: =RANK(I11,11:11,1) -> 2 | J13: =RANK(J11,11:11,1) -> 1
B14: sum_rank | C14: =C12+C13 -> 12 | D14: =D12+D13 -> 16 | E14: =E12+E13 -> 6 | F14: =F12+F13 -> 10 | G14: =G12+G13 -> 8 | H14: =H12+H13 -> 14 | I14: =I12+I13 -> 4 | J14: =J12+J13 -> 2
B15: RANK | C15: =RANK(C14,14:14,1) -> 6 | D15: =RANK(D14,14:14,1) -> 8 | E15: =RANK(E14,14:14,1) -> 3 | F15: =RANK(F14,14:14,1) -> 5 | G15: =RANK(G14,14:14,1) -> 4 | H15: =RANK(H14,14:14,1) -> 7 | I15: =RANK(I14,14:14,1) -> 2 | J15: =RANK(J14,14:14,1) -> 1
B16: ‘-/=/+ | C16: =IF(C15>C15,"-",IF(C15=C15,"=","+")) -> = | D16: =IF(D15>C15,"-",IF(D15=C15,"=","+")) -> - | E16: =IF(E15>C15,"-",IF(E15=C15,"=","+")) -> + | F16: =IF(F15>C15,"-",IF(F15=C15,"=","+")) -> + | G16: =IF(G15>C15,"-",IF(G15=C15,"=","+")) -> + | H16: =IF(H15>C15,"-",IF(H15=C15,"=","+")) -> - | I16: =IF(I15>C15,"-",IF(I15=C15,"=","+")) -> + | J16: =IF(J15>C15,"-",IF(J15=C15,"=","+")) -> +
A17: F3 | B17: Mean | C17: =辅助表!C7 -> 81278.807 | D17: =辅助表!D7 -> 88937.976 | E17: =辅助表!E7 -> 79389.602 | F17: =辅助表!F7 -> 71485.162 | G17: =辅助表!G7 -> 91541.14 | H17: =辅助表!H7 -> 72370.102 | I17: =辅助表!I7 -> 69450.501 | J17: =辅助表!J7 -> 66572.544
B18: Std | C18: =辅助表!C8 -> 8529.3576 | D18: =辅助表!D8 -> 6058.1333 | E18: =辅助表!E8 -> 10646.74 | F18: =辅助表!F8 -> 7402.9582 | G18: =辅助表!G8 -> 6956.1385 | H18: =辅助表!H8 -> 6112.4874 | I18: =辅助表!I8 -> 10095.786 | J18: =辅助表!J8 -> 9545.5029
B19: mean_Rank | C19: =RANK(C17,17:17,1) -> 6 | D19: =RANK(D17,17:17,1) -> 7 | E19: =RANK(E17,17:17,1) -> 5 | F19: =RANK(F17,17:17,1) -> 3 | G19: =RANK(G17,17:17,1) -> 8 | H19: =RANK(H17,17:17,1) -> 4 | I19: =RANK(I17,17:17,1) -> 2 | J19: =RANK(J17,17:17,1) -> 1
B20: std_rank | C20: =RANK(C18,18:18,1) -> 5 | D20: =RANK(D18,18:18,1) -> 1 | E20: =RANK(E18,18:18,1) -> 8 | F20: =RANK(F18,18:18,1) -> 4 | G20: =RANK(G18,18:18,1) -> 3 | H20: =RANK(H18,18:18,1) -> 2 | I20: =RANK(I18,18:18,1) -> 7 | J20: =RANK(J18,18:18,1) -> 6
B21: sum_rank | C21: =C19+C20 -> 11 | D21: =D19+D20 -> 8 | E21: =E19+E20 -> 13 | F21: =F19+F20 -> 7 | G21: =G19+G20 -> 11 | H21: =H19+H20 -> 6 | I21: =I19+I20 -> 9 | J21: =J19+J20 -> 7
B22: RANK | C22: =RANK(C21,21:21,1) -> 6 | D22: =RANK(D21,21:21,1) -> 4 | E22: =RANK(E21,21:21,1) -> 8 | F22: =RANK(F21,21:21,1) -> 2 | G22: =RANK(G21,21:21,1) -> 6 | H22: =RANK(H21,21:21,1) -> 1 | I22: =RANK(I21,21:21,1) -> 5 | J22: =RANK(J21,21:21,1) -> 2
B23: ‘-/=/+ | C23: =IF(C22>C22,"-",IF(C22=C22,"=","+")) -> = | D23: =IF(D22>C22,"-",IF(D22=C22,"=","+")) -> + | E23: =IF(E22>C22,"-",IF(E22=C22,"=","+")) -> - | F23: =IF(F22>C22,"-",IF(F22=C22,"=","+")) -> + | G23: =IF(G22>C22,"-",IF(G22=C22,"=","+")) -> = | H23: =IF(H22>C22,"-",IF(H22=C22,"=","+")) -> + | I23: =IF(I22>C22,"-",IF(I22=C22,"=","+")) -> + | J23: =IF(J22>C22,"-",IF(J22=C22,"=","+")) -> +
A24: F4 | B24: Mean | C24: =辅助表!C9 -> 789.16252 | D24: =辅助表!D9 -> 3374.8982 | E24: =辅助表!E9 -> 555.40489 | F24: =辅助表!F9 -> 647.85349 | G24: =辅助表!G9 -> 635.54257 | H24: =辅助表!H9 -> 661.24302 | I24: =辅助表!I9 -> 556.80898 | J24: =辅助表!J9 -> 544.22697
B25: Std | C25: =辅助表!C10 -> 128.62 | D25: =辅助表!D10 -> 1146.5088 | E25: =辅助表!E10 -> 49.901798 | F25: =辅助表!F10 -> 62.97621 | G25: =辅助表!G10 -> 55.764655 | H25: =辅助表!H10 -> 81.612139 | I25: =辅助表!I10 -> 38.318549 | J25: =辅助表!J10 -> 27.241981
B26: mean_Rank | C26: =RANK(C24,24:24,1) -> 7 | D26: =RANK(D24,24:24,1) -> 8 | E26: =RANK(E24,24:24,1) -> 2 | F26: =RANK(F24,24:24,1) -> 5 | G26: =RANK(G24,24:24,1) -> 4 | H26: =RANK(H24,24:24,1) -> 6 | I26: =RANK(I24,24:24,1) -> 3 | J26: =RANK(J24,24:24,1) -> 1
B27: std_rank | C27: =RANK(C25,25:25,1) -> 7 | D27: =RANK(D25,25:25,1) -> 8 | E27: =RANK(E25,25:25,1) -> 3 | F27: =RANK(F25,25:25,1) -> 5 | G27: =RANK(G25,25:25,1) -> 4 | H27: =RANK(H25,25:25,1) -> 6 | I27: =RANK(I25,25:25,1) -> 2 | J27: =RANK(J25,25:25,1) -> 1
B28: sum_rank | C28: =C26+C27 -> 14 | D28: =D26+D27 -> 16 | E28: =E26+E27 -> 5 | F28: =F26+F27 -> 10 | G28: =G26+G27 -> 8 | H28: =H26+H27 -> 12 | I28: =I26+I27 -> 5 | J28: =J26+J27 -> 2
B29: RANK | C29: =RANK(C28,28:28,1) -> 7 | D29: =RANK(D28,28:28,1) -> 8 | E29: =RANK(E28,28:28,1) -> 2 | F29: =RANK(F28,28:28,1) -> 5 | G29: =RANK(G28,28:28,1) -> 4 | H29: =RANK(H28,28:28,1) -> 6 | I29: =RANK(I28,28:28,1) -> 2 | J29: =RANK(J28,28:28,1) -> 1
B30: ‘-/=/+ | C30: =IF(C29>C29,"-",IF(C29=C29,"=","+")) -> = | D30: =IF(D29>C29,"-",IF(D29=C29,"=","+")) -> - | E30: =IF(E29>C29,"-",IF(E29=C29,"=","+")) -> + | F30: =IF(F29>C29,"-",IF(F29=C29,"=","+")) -> + | G30: =IF(G29>C29,"-",IF(G29=C29,"=","+")) -> + | H30: =IF(H29>C29,"-",IF(H29=C29,"=","+")) -> + | I30: =IF(I29>C29,"-",IF(I29=C29,"=","+")) -> + | J30: =IF(J29>C29,"-",IF(J29=C29,"=","+")) -> +
A31: F5 | B31: Mean | C31: =辅助表!C11 -> 628.66725 | D31: =辅助表!D11 -> 959.27739 | E31: =辅助表!E11 -> 669.35651 | F31: =辅助表!F11 -> 606.47936 | G31: =辅助表!G11 -> 781.02256 | H31: =辅助表!H11 -> 612.5943 | I31: =辅助表!I11 -> 648.24283 | J31: =辅助表!J11 -> 656.01685
B32: Std | C32: =辅助表!C12 -> 30.26242 | D32: =辅助表!D12 -> 15.916185 | E32: =辅助表!E12 -> 39.415566 | F32: =辅助表!F12 -> 26.264335 | G32: =辅助表!G12 -> 46.814431 | H32: =辅助表!H12 -> 30.143565 | I32: =辅助表!I12 -> 38.608788 | J32: =辅助表!J12 -> 35.15366
B33: mean_Rank | C33: =RANK(C31,31:31,1) -> 3 | D33: =RANK(D31,31:31,1) -> 8 | E33: =RANK(E31,31:31,1) -> 6 | F33: =RANK(F31,31:31,1) -> 1 | G33: =RANK(G31,31:31,1) -> 7 | H33: =RANK(H31,31:31,1) -> 2 | I33: =RANK(I31,31:31,1) -> 4 | J33: =RANK(J31,31:31,1) -> 5
B34: std_rank | C34: =RANK(C32,32:32,1) -> 4 | D34: =RANK(D32,32:32,1) -> 1 | E34: =RANK(E32,32:32,1) -> 7 | F34: =RANK(F32,32:32,1) -> 2 | G34: =RANK(G32,32:32,1) -> 8 | H34: =RANK(H32,32:32,1) -> 3 | I34: =RANK(I32,32:32,1) -> 6 | J34: =RANK(J32,32:32,1) -> 5
B35: sum_rank | C35: =C33+C34 -> 7 | D35: =D33+D34 -> 9 | E35: =E33+E34 -> 13 | F35: =F33+F34 -> 3 | G35: =G33+G34 -> 15 | H35: =H33+H34 -> 5 | I35: =I33+I34 -> 10 | J35: =J33+J34 -> 10
B36: RANK | C36: =RANK(C35,35:35,1) -> 3 | D36: =RANK(D35,35:35,1) -> 4 | E36: =RANK(E35,35:35,1) -> 7 | F36: =RANK(F35,35:35,1) -> 1 | G36: =RANK(G35,35:35,1) -> 8 | H36: =RANK(H35,35:35,1) -> 2 | I36: =RANK(I35,35:35,1) -> 5 | J36: =RANK(J35,35:35,1) -> 5
B37: ‘-/=/+ | C37: =IF(C36>C36,"-",IF(C36=C36,"=","+")) -> = | D37: =IF(D36>C36,"-",IF(D36=C36,"=","+")) -> - | E37: =IF(E36>C36,"-",IF(E36=C36,"=","+")) -> - | F37: =IF(F36>C36,"-",IF(F36=C36,"=","+")) -> + | G37: =IF(G36>C36,"-",IF(G36=C36,"=","+")) -> - | H37: =IF(H36>C36,"-",IF(H36=C36,"=","+")) -> + | I37: =IF(I36>C36,"-",IF(I36=C36,"=","+")) -> - | J37: =IF(J36>C36,"-",IF(J36=C36,"=","+")) -> -
A38: F6 | B38: Mean | C38: =辅助表!C13 -> 628.04987 | D38: =辅助表!D13 -> 666.75971 | E38: =辅助表!E13 -> 604.95731 | F38: =辅助表!F13 -> 615.67128 | G38: =辅助表!G13 -> 644.98691 | H38: =辅助表!H13 -> 614.86997 | I38: =辅助表!I13 -> 603.97892 | J38: =辅助表!J13 -> 603.96237
B39: Std | C39: =辅助表!C14 -> 5.9044319 | D39: =辅助表!D14 -> 6.3094423 | E39: =辅助表!E14 -> 2.7697522 | F39: =辅助表!F14 -> 5.0863131 | G39: =辅助表!G14 -> 8.9013293 | H39: =辅助表!H14 -> 4.6966603 | I39: =辅助表!I14 -> 1.6536937 | J39: =辅助表!J14 -> 2.6525179
B40: mean_Rank | C40: =RANK(C38,38:38,1) -> 6 | D40: =RANK(D38,38:38,1) -> 8 | E40: =RANK(E38,38:38,1) -> 3 | F40: =RANK(F38,38:38,1) -> 5 | G40: =RANK(G38,38:38,1) -> 7 | H40: =RANK(H38,38:38,1) -> 4 | I40: =RANK(I38,38:38,1) -> 2 | J40: =RANK(J38,38:38,1) -> 1
...

Sheet 辅助表
A1: Fun | B1: Index | C1: Algorithms
C2: SO | D2: TCM-SO | E2: BDS-SO | F2: EOBL-SO | G2: TB-SO | H2: TE-SO | I2: BE-SO | J2: TBESO
A3: F1 | B3: Mean | C3: 2.3020981e+09 | D3: 2.5983919e+10 | E3: 35688240 | F3: 4.9530994e+08 | G3: 4.2767912e+08 | H3: 4.8563039e+08 | I3: 25992311 | J3: 24394091
B4: Std | C4: 1.02555e+09 | D4: 6.7771665e+09 | E4: 20432904 | F4: 2.7875701e+08 | G4: 2.0654322e+08 | H4: 2.6011969e+08 | I4: 14068292 | J4: 14882927
A5: F2 | B5: Mean | C5: 1.1421454e+32 | D5: 5.5838833e+37 | E5: 3.6232161e+28 | F5: 6.0032476e+31 | G5: 7.7946279e+30 | H5: 7.6083724e+32 | I5: 6.8063257e+27 | J5: 1.0184732e+27
B6: Std | C6: 3.6284939e+32 | D6: 2.4614382e+38 | E6: 1.0309384e+29 | F6: 2.3171128e+32 | G6: 3.7168277e+31 | H6: 4.157885e+33 | I6: 3.2331306e+28 | J6: 3.1997278e+27
A7: F3 | B7: Mean | C7: 81278.807 | D7: 88937.976 | E7: 79389.602 | F7: 71485.162 | G7: 91541.14 | H7: 72370.102 | I7: 69450.501 | J7: 66572.544
B8: Std | C8: 8529.3576 | D8: 6058.1333 | E8: 10646.74 | F8: 7402.9582 | G8: 6956.1385 | H8: 6112.4874 | I8: 10095.786 | J8: 9545.5029
A9: F4 | B9: Mean | C9: 789.16252 | D9: 3374.8982 | E9: 555.40489 | F9: 647.85349 | G9: 635.54257 | H9: 661.24302 | I9: 556.80898 | J9: 544.22697
B10: Std | C10: 128.62 | D10: 1146.5088 | E10: 49.901798 | F10: 62.97621 | G10: 55.764655 | H10: 81.612139 | I10: 38.318549 | J10: 27.241981
A11: F5 | B11: Mean | C11: 628.66725 | D11: 959.27739 | E11: 669.35651 | F11: 606.47936 | G11: 781.02256 | H11: 612.5943 | I11: 648.24283 | J11: 656.01685
B12: Std | C12: 30.26242 | D12: 15.916185 | E12: 39.415566 | F12: 26.264335 | G12: 46.814431 | H12: 30.143565 | I12: 38.608788 | J12: 35.15366
A13: F6 | B13: Mean | C13: 628.04987 | D13: 666.75971 | E13: 604.95731 | F13: 615.67128 | G13: 644.98691 | H13: 614.86997 | I13: 603.97892 | J13: 603.96237
B14: Std | C14: 5.9044319 | D14: 6.3094423 | E14: 2.7697522 | F14: 5.0863131 | G14: 8.9013293 | H14: 4.6966603 | I14: 1.6536937 | J14: 2.6525179
A15: F7 | B15: Mean | C15: 1102.5824 | D15: 1391.1802 | E15: 951.93518 | F15: 946.33451 | G15: 972.74784 | H15: 962.09158 | I15: 945.78122 | J15: 942.77719
B16: Std | C16: 52.682322 | D16: 62.169189 | E16: 37.483241 | F16: 29.864304 | G16: 63.456735 | H16: 32.308003 | I16: 30.375834 | J16: 28.927907
A17: F8 | B17: Mean | C17: 923.89283 | D17: 1179.0605 | E17: 946.61107 | F17: 897.10228 | G17: 1082.1297 | H17: 896.92843 | I17: 942.05985 | J17: 939.91691
B18: Std | C18: 28.026478 | D18: 10.178011 | E18: 39.176028 | F18: 21.45187 | G18: 55.934659 | H18: 24.194912 | I18: 28.487562 | J18: 35.827593
A19: F9 | B19: Mean | C19: 4782.313 | D19: 12050.807 | E19: 1670.6831 | F19: 1970.405 | G19: 11931.686 | H19: 1952.8275 | I19: 1344.0779 | J19: 1346.5582
B20: Std | C20: 1433.0723 | D20: 1162.5029 | E20: 512.83792 | F20: 489.69269 | G20: 1612.9629 | H20: 571.55853 | I20: 448.55359 | J20: 318.64075
A21: F10 | B21: Mean | C21: 8160.2524 | D21: 5719.4171 | E21: 8387.408 | F21: 8585.0958 | G21: 6210.004 | H21: 8749.0584 | I21: 8554.8877 | J21: 8557.1374
B22: Std | C22: 972.19869 | D22: 910.58897 | E22: 636.71531 | F22: 364.79503 | G22: 1092.442 | H22: 257.01321 | I22: 350.19643 | J22: 491.54595
A23: F11 | B23: Mean | C23: 2137.6327 | D23: 8885.0505 | E23: 1856.6566 | F23: 1897.6677 | G23: 2091.0846 | H23: 1888.9663 | I23: 1618.7583 | J23: 1603.6774
B24: Std | C24: 410.56216 | D24: 3169.6618 | E24: 324.21878 | F24: 264.97191 | G24: 415.4837 | H24: 386.98089 | I24: 208.62681 | J24: 190.37641
A25: F12 | B25: Mean | C25: 32267174 | D25: 4.3671557e+08 | E25: 5196727.3 | F25: 20023039 | G25: 8600945.4 | H25: 13347706 | I25: 4718036.4 | J25: 5369524.5
B26: Std | C26: 30461629 | D26: 3.6587096e+08 | E26: 4355990.3 | F26: 16393447 | G26: 5174653.4 | H26: 12281807 | I26: 3324787.7 | J26: 5863423.8
A27: F13 | B27: Mean | C27: 408059.41 | D27: 69924136 | E27: 95042.519 | F27: 104836.87 | G27: 116311.35 | H27: 317782.12 | I27: 73296.874 | J27: 80624.342
B28: Std | C28: 838312.19 | D28: 1.4546447e+08 | E28: 101339.3 | F28: 71053.055 | G28: 73021.705 | H28: 1040408.5 | I28: 42385.227 | J28: 59224.124
A29: F14 | B29: Mean | C29: 233681.29 | D29: 367097.96 | E29: 110701.65 | F29: 234324.87 | G29: 283622.67 | H29: 177834.43 | I29: 111347.19 | J29: 80498.639
B30: Std | C30: 236405.9 | D30: 463369.6 | E30: 100674.95 | F30: 304715.02 | G30: 263335.67 | H30: 199903.37 | I30: 113439.53 | J30: 67923.147
A31: F15 | B31: Mean | C31: 28972.361 | D31: 205156.1 | E31: 28948.455 | F31: 25659.227 | G31: 30715.047 | H31: 27733.594 | I31: 16445.595 | J31: 18548.668
B32: Std | C32: 21752.195 | D32: 384599.82 | E32: 20753.917 | F32: 26615.804 | G32: 16769.443 | H32: 30195.261 | I32: 9922.5712 | J32: 20406.119
A33: F16 | B33: Mean | C33: 2801.1354 | D33: 4042.3707 | E33: 3119.328 | F33: 2966.2487 | G33: 3003.404 | H33: 2745.9306 | I33: 3168.5943 | J33: 3281.9188
B34: Std | C34: 364.36572 | D34: 425.19205 | E34: 463.35781 | F34: 459.03214 | G34: 471.39402 | H34: 365.98753 | I34: 422.43826 | J34: 388.595
A35: F17 | B35: Mean | C35: 2406.837 | D35: 2609.0396 | E35: 2222.2096 | F35: 2223.7906 | G35: 2137.6179 | H35: 2112.9262 | I35: 2163.8913 | J35: 2166.9648
B36: Std | C36: 280.7172 | D36: 259.49466 | E36: 221.89136 | F36: 179.74631 | G36: 157.95009 | H36: 188.65478 | I36: 215.89864 | J36: 181.97287
A37: F18 | B37: Mean | C37: 3875282.5 | D37: 924576.23 | E37: 1999161.8 | F37: 1834081.1 | G37: 460154.25 | H37: 1865935.7 | I37: 2940246 | J37: 1281571.2
B38: Std | C38: 4198935.6 | D38: 1093998.8 | E38: 1674858.9 | F38: 1758259.3 | G38: 320135.82 | H38: 1685708.2 | I38: 2769895.4 | J38: 1372769
A39: F19 | B39: Mean | C39: 55317.864 | D39: 4248615.5 | E39: 22364.008 | F39: 36510.737 | G39: 45940.833 | H39: 37343.624 | I39: 17441.217 | J39: 10423.089
B40: Std | C40: 94303.455 | D40: 7242116.9 | E40: 19260.243 | F40: 71713.335 | G40: 14681.689 | H40: 53089.526 | I40: 18908.721 | J40: 9877.3714
...

Sheet 原数据
A1: Fun | B1: Index | C1: Algorithms
C2: SO | D2: TCM-SO | E2: BDS-SO | F2: EOBL-SO | G2: TB-SO | H2: TE-SO | I2: BE-SO | J2: TBESO
A3: F1 | B3: Mean | C3: 26549459 | D3: 10493520 | E3: 525749.17 | F3: 1643203.7 | G3: 504885.1 | H3: 2118907.5 | I3: 341814.76 | J3: 499751.61
B4: Std | C4: 39184382 | D4: 10009250 | E4: 403093.94 | F4: 1275516.3 | G4: 431626.86 | H4: 1640648.9 | I4: 246258.17 | J4: 479166.84
B5: Rank | C5: =RANK(C3,3:3,1) -> 8 | D5: =RANK(D3,3:3,1) -> 7 | E5: =RANK(E3,3:3,1) -> 4 | F5: =RANK(F3,3:3,1) -> 5 | G5: =RANK(G3,3:3,1) -> 3 | H5: =RANK(H3,3:3,1) -> 6 | I5: =RANK(I3,3:3,1) -> 1 | J5: =RANK(J3,3:3,1) -> 2
A6: F2 | B6: Mean | C6: 1.0975866e+26 | D6: 4.2688869e+25 | E6: 5.1082231e+18 | F6: 4.8296738e+23 | G6: 1.0117115e+19 | H6: 1.3046582e+24 | I6: 5.8567836e+18 | J6: 1.1410249e+19
B7: Std | C7: 5.8604966e+26 | D7: 2.189162e+26 | E7: 1.221406e+19 | F7: 1.989505e+24 | G7: 2.8012614e+19 | H7: 5.4628558e+24 | I7: 1.2796267e+19 | J7: 2.7152475e+19
B8: Rank | C8: =RANK(C6,6:6,1) -> 8 | D8: =RANK(D6,6:6,1) -> 7 | E8: =RANK(E6,6:6,1) -> 1 | F8: =RANK(F6,6:6,1) -> 5 | G8: =RANK(G6,6:6,1) -> 3 | H8: =RANK(H6,6:6,1) -> 6 | I8: =RANK(I6,6:6,1) -> 2 | J8: =RANK(J6,6:6,1) -> 4
A9: F3 | B9: Mean | C9: 71215.224 | D9: 69664.126 | E9: 68251.17 | F9: 62228.875 | G9: 64201.947 | H9: 62135.474 | I9: 60040.475 | J9: 60468.468
B10: Std | C10: 9966.1318 | D10: 10524.63 | E10: 9180.075 | F10: 8725.5856 | G10: 9802.6658 | H10: 7284.3572 | I10: 7566.3214 | J10: 8664.8367
B11: Rank | C11: =RANK(C9,9:9,1) -> 8 | D11: =RANK(D9,9:9,1) -> 7 | E11: =RANK(E9,9:9,1) -> 6 | F11: =RANK(F9,9:9,1) -> 4 | G11: =RANK(G9,9:9,1) -> 5 | H11: =RANK(H9,9:9,1) -> 3 | I11: =RANK(I9,9:9,1) -> 1 | J11: =RANK(J9,9:9,1) -> 2
A12: F4 | B12: Mean | C12: 582.30587 | D12: 583.88335 | E12: 495.74834 | F12: 553.67987 | G12: 504.75829 | H12: 544.13585 | I12: 501.53685 | J12: 496.50377
B13: Std | C13: 54.13838 | D13: 52.112621 | E13: 25.431691 | F13: 29.805237 | G13: 23.522131 | H13: 40.25393 | I13: 19.267021 | J13: 18.482571
B14: Rank | C14: =RANK(C12,12:12,1) -> 7 | D14: =RANK(D12,12:12,1) -> 8 | E14: =RANK(E12,12:12,1) -> 1 | F14: =RANK(F12,12:12,1) -> 6 | G14: =RANK(G12,12:12,1) -> 4 | H14: =RANK(H12,12:12,1) -> 5 | I14: =RANK(I12,12:12,1) -> 3 | J14: =RANK(J12,12:12,1) -> 2
A15: F5 | B15: Mean | C15: 616.34095 | D15: 609.16889 | E15: 570.09702 | F15: 569.82187 | G15: 568.50904 | H15: 574.23729 | I15: 558.86291 | J15: 562.47738
B16: Std | C16: 30.023176 | D16: 23.951571 | E16: 16.417602 | F16: 15.876285 | G16: 16.64493 | H16: 12.432243 | I16: 16.222768 | J16: 20.371692
B17: Rank | C17: =RANK(C15,15:15,1) -> 8 | D17: =RANK(D15,15:15,1) -> 7 | E17: =RANK(E15,15:15,1) -> 5 | F17: =RANK(F15,15:15,1) -> 4 | G17: =RANK(G15,15:15,1) -> 3 | H17: =RANK(H15,15:15,1) -> 6 | I17: =RANK(I15,15:15,1) -> 1 | J17: =RANK(J15,15:15,1) -> 2
A18: F6 | B18: Mean | C18: 622.76081 | D18: 620.18873 | E18: 600.99769 | F18: 610.55828 | G18: 601.24355 | H18: 609.43425 | I18: 601.04274 | J18: 601.27005
B19: Std | C19: 6.2261909 | D19: 8.3850693 | E19: 0.59604844 | F19: 5.1331596 | G19: 0.75718396 | H19: 4.984111 | I19: 0.76472559 | J19: 0.79688431
B20: Rank | C20: =RANK(C18,18:18,1) -> 8 | D20: =RANK(D18,18:18,1) -> 7 | E20: =RANK(E18,18:18,1) -> 1 | F20: =RANK(F18,18:18,1) -> 6 | G20: =RANK(G18,18:18,1) -> 3 | H20: =RANK(H18,18:18,1) -> 5 | I20: =RANK(I18,18:18,1) -> 2 | J20: =RANK(J18,18:18,1) -> 4
A21: F7 | B21: Mean | C21: 995.78007 | D21: 907.99802 | E21: 899.93947 | F21: 881.14379 | G21: 876.68822 | H21: 886.36436 | I21: 877.2121 | J21: 899.35786
B22: Std | C22: 58.504382 | D22: 30.714488 | E22: 44.533354 | F22: 39.665874 | G22: 45.12225 | H22: 46.385254 | I22: 37.560433 | J22: 41.44413
B23: Rank | C23: =RANK(C21,21:21,1) -> 8 | D23: =RANK(D21,21:21,1) -> 7 | E23: =RANK(E21,21:21,1) -> 6 | F23: =RANK(F21,21:21,1) -> 3 | G23: =RANK(G21,21:21,1) -> 1 | H23: =RANK(H21,21:21,1) -> 4 | I23: =RANK(I21,21:21,1) -> 2 | J23: =RANK(J21,21:21,1) -> 5
A24: F8 | B24: Mean | C24: 911.64157 | D24: 886.6373 | E24: 863.24514 | F24: 864.40907 | G24: 859.57632 | H24: 864.02729 | I24: 851.66912 | J24: 850.12171
B25: Std | C25: 25.8282 | D25: 14.46545 | E25: 11.681163 | F25: 12.919401 | G25: 15.745946 | H25: 10.169544 | I25: 16.008524 | J25: 11.347363
B26: Rank | C26: =RANK(C24,24:24,1) -> 8 | D26: =RANK(D24,24:24,1) -> 7 | E26: =RANK(E24,24:24,1) -> 4 | F26: =RANK(F24,24:24,1) -> 6 | G26: =RANK(G24,24:24,1) -> 3 | H26: =RANK(H24,24:24,1) -> 5 | I26: =RANK(I24,24:24,1) -> 2 | J26: =RANK(J24,24:24,1) -> 1
A27: F9 | B27: Mean | C27: 3822.9752 | D27: 2830.8311 | E27: 1195.9292 | F27: 1605.945 | G27: 1138.294 | H27: 1487.1833 | I27: 1037.2007 | J27: 1051.8783
B28: Std | C28: 1618.4232 | D28: 994.2606 | E28: 318.91011 | F28: 553.70642 | G28: 257.67348 | H28: 314.03078 | I28: 131.93279 | J28: 170.59933
B29: Rank | C29: =RANK(C27,27:27,1) -> 8 | D29: =RANK(D27,27:27,1) -> 7 | E29: =RANK(E27,27:27,1) -> 4 | F29: =RANK(F27,27:27,1) -> 6 | G29: =RANK(G27,27:27,1) -> 3 | H29: =RANK(H27,27:27,1) -> 5 | I29: =RANK(I27,27:27,1) -> 1 | J29: =RANK(J27,27:27,1) -> 2
A30: F10 | B30: Mean | C30: 4786.5616 | D30: 4197.4915 | E30: 7574.9121 | F30: 8060.4826 | G30: 7316.9655 | H30: 7981.8626 | I30: 8264.8127 | J30: 8141.1777
B31: Std | C31: 1420.8521 | D31: 854.14204 | E31: 950.32532 | F31: 706.59886 | G31: 1357.9515 | H31: 1125.5818 | I31: 447.75152 | J31: 590.28691
B32: Rank | C32: =RANK(C30,30:30,1) -> 2 | D32: =RANK(D30,30:30,1) -> 1 | E32: =RANK(E30,30:30,1) -> 4 | F32: =RANK(F30,30:30,1) -> 6 | G32: =RANK(G30,30:30,1) -> 3 | H32: =RANK(H30,30:30,1) -> 5 | I32: =RANK(I30,30:30,1) -> 8 | J32: =RANK(J30,30:30,1) -> 7
A33: F11 | B33: Mean | C33: 1489.6621 | D33: 1392.4773 | E33: 1248.8392 | F33: 1339.5952 | G33: 1279.6581 | H33: 1343.4621 | I33: 1247.0569 | J33: 1230.7309
B34: Std | C34: 155.28736 | D34: 88.699483 | E34: 45.389338 | F34: 69.834003 | G34: 53.053826 | H34: 70.979239 | I34: 42.95069 | J34: 39.366945
B35: Rank | C35: =RANK(C33,33:33,1) -> 8 | D35: =RANK(D33,33:33,1) -> 7 | E35: =RANK(E33,33:33,1) -> 3 | F35: =RANK(F33,33:33,1) -> 5 | G35: =RANK(G33,33:33,1) -> 4 | H35: =RANK(H33,33:33,1) -> 6 | I35: =RANK(I33,33:33,1) -> 2 | J35: =RANK(J33,33:33,1) -> 1
A36: F12 | B36: Mean | C36: 3505665 | D36: 4016659.4 | E36: 1288372.3 | F36: 2934220.1 | G36: 1131238.1 | H36: 2494829.1 | I36: 1093724.6 | J36: 1203634.7
B37: Std | C37: 4264505.8 | D37: 4692186.8 | E37: 1052580 | F37: 3154280.6 | G37: 967066.54 | H37: 2037691 | I37: 761207.21 | J37: 671546.06
B38: Rank | C38: =RANK(C36,36:36,1) -> 7 | D38: =RANK(D36,36:36,1) -> 8 | E38: =RANK(E36,36:36,1) -> 4 | F38: =RANK(F36,36:36,1) -> 6 | G38: =RANK(G36,36:36,1) -> 2 | H38: =RANK(H36,36:36,1) -> 5 | I38: =RANK(I36,36:36,1) -> 1 | J38: =RANK(J36,36:36,1) -> 3
A39: F13 | B39: Mean | C39: 27785.775 | D39: 49853.222 | E39: 21137.889 | F39: 37153.7 | G39: 21425.836 | H39: 33441.029 | I39: 17202.903 | J39: 21487.812
B40: Std | C40: 15579.412 | D40: 25127.323 | E40: 15509.041 | F40: 24933.544 | G40: 16087.679 | H40: 20500.791 | I40: 14280.436 | J40: 15988.305
...
